Internal Server Error: /api/campaign-requests/
Traceback (most recent call last):
  File "D:\Python\Lib\site-packages\django\db\backends\utils.py", line 89, in _execute
    return self.cursor.execute(sql, params)
           ^^^^^^^^^^^^^^^^^^^^^^^^^^^^^^^^
  File "D:\Python\Lib\site-packages\django\db\backends\sqlite3\base.py", line 328, in execute
    return super().execute(query, params)
           ^^^^^^^^^^^^^^^^^^^^^^^^^^^^^^
sqlite3.OperationalError: no such table: campaigns_campaignrequest

The above exception was the direct cause of the following exception:

Traceback (most recent call last):
  File "D:\Python\Lib\site-packages\django\core\handlers\exception.py", line 55, in inner
    response = get_response(request)
               ^^^^^^^^^^^^^^^^^^^^^
  File "D:\Python\Lib\site-packages\django\core\handlers\base.py", line 197, in _get_response
    response = wrapped_callback(request, *callback_args, **callback_kwargs)
               ^^^^^^^^^^^^^^^^^^^^^^^^^^^^^^^^^^^^^^^^^^^^^^^^^^^^^^^^^^^^
  File "D:\Python\Lib\site-packages\django\views\decorators\csrf.py", line 56, in wrapper_view
    return view_func(*args, **kwargs)
           ^^^^^^^^^^^^^^^^^^^^^^^^^^
  File "D:\Python\Lib\site-packages\django\views\generic\base.py", line 104, in view
    return self.dispatch(request, *args, **kwargs)
           ^^^^^^^^^^^^^^^^^^^^^^^^^^^^^^^^^^^^^^^
  File "D:\Python\Lib\site-packages\rest_framework\views.py", line 509, in dispatch
    response = self.handle_exception(exc)
               ^^^^^^^^^^^^^^^^^^^^^^^^^^
  File "D:\Python\Lib\site-packages\rest_framework\views.py", line 469, in handle_exception
    self.raise_uncaught_exception(exc)
  File "D:\Python\Lib\site-packages\rest_framework\views.py", line 480, in raise_uncaught_exception
    raise exc
  File "D:\Python\Lib\site-packages\rest_framework\views.py", line 506, in dispatch
    response = handler(request, *args, **kwargs)
               ^^^^^^^^^^^^^^^^^^^^^^^^^^^^^^^^^
  File "D:\Project\Final\FundFusion\campaigns\views.py", line 17, in post
    campaign_request = serializer.save(requester=request.user)
                       ^^^^^^^^^^^^^^^^^^^^^^^^^^^^^^^^^^^^^^^
  File "D:\Python\Lib\site-packages\rest_framework\serializers.py", line 212, in save
    self.instance = self.create(validated_data)
                    ^^^^^^^^^^^^^^^^^^^^^^^^^^^
  File "D:\Python\Lib\site-packages\rest_framework\serializers.py", line 962, in create
    instance = ModelClass._default_manager.create(**validated_data)
               ^^^^^^^^^^^^^^^^^^^^^^^^^^^^^^^^^^^^^^^^^^^^^^^^^^^^
  File "D:\Python\Lib\site-packages\django\db\models\manager.py", line 87, in manager_method
    return getattr(self.get_queryset(), name)(*args, **kwargs)
           ^^^^^^^^^^^^^^^^^^^^^^^^^^^^^^^^^^^^^^^^^^^^^^^^^^^
  File "D:\Python\Lib\site-packages\django\db\models\query.py", line 658, in create
    obj.save(force_insert=True, using=self.db)
  File "D:\Python\Lib\site-packages\django\db\models\base.py", line 814, in save
    self.save_base(
  File "D:\Python\Lib\site-packages\django\db\models\base.py", line 877, in save_base
    updated = self._save_table(
              ^^^^^^^^^^^^^^^^^
  File "D:\Python\Lib\site-packages\django\db\models\base.py", line 1020, in _save_table
    results = self._do_insert(
              ^^^^^^^^^^^^^^^^
  File "D:\Python\Lib\site-packages\django\db\models\base.py", line 1061, in _do_insert
    return manager._insert(
           ^^^^^^^^^^^^^^^^
  File "D:\Python\Lib\site-packages\django\db\models\manager.py", line 87, in manager_method
    return getattr(self.get_queryset(), name)(*args, **kwargs)
           ^^^^^^^^^^^^^^^^^^^^^^^^^^^^^^^^^^^^^^^^^^^^^^^^^^^
  File "D:\Python\Lib\site-packages\django\db\models\query.py", line 1805, in _insert
    return query.get_compiler(using=using).execute_sql(returning_fields)
           ^^^^^^^^^^^^^^^^^^^^^^^^^^^^^^^^^^^^^^^^^^^^^^^^^^^^^^^^^^^^^
  File "D:\Python\Lib\site-packages\django\db\models\sql\compiler.py", line 1822, in execute_sql
    cursor.execute(sql, params)
  File "D:\Python\Lib\site-packages\django\db\backends\utils.py", line 67, in execute
    return self._execute_with_wrappers(
           ^^^^^^^^^^^^^^^^^^^^^^^^^^^^
  File "D:\Python\Lib\site-packages\django\db\backends\utils.py", line 80, in _execute_with_wrappers
    return executor(sql, params, many, context)
           ^^^^^^^^^^^^^^^^^^^^^^^^^^^^^^^^^^^^
  File "D:\Python\Lib\site-packages\django\db\backends\utils.py", line 84, in _execute
    with self.db.wrap_database_errors:
         ^^^^^^^^^^^^^^^^^^^^^^^^^^^^
  File "D:\Python\Lib\site-packages\django\db\utils.py", line 91, in __exit__
    raise dj_exc_value.with_traceback(traceback) from exc_value
  File "D:\Python\Lib\site-packages\django\db\backends\utils.py", line 89, in _execute
    return self.cursor.execute(sql, params)
           ^^^^^^^^^^^^^^^^^^^^^^^^^^^^^^^^
  File "D:\Python\Lib\site-packages\django\db\backends\sqlite3\base.py", line 328, in execute
    return super().execute(query, params)
           ^^^^^^^^^^^^^^^^^^^^^^^^^^^^^^
django.db.utils.OperationalError: no such table: campaigns_campaignrequest
"POST /api/campaign-requests/ HTTP/1.1" 500 145
Internal Server Error: /api/campaign-requests/
Traceback (most recent call last):
  File "D:\Python\Lib\site-packages\django\db\backends\utils.py", line 89, in _execute
    return self.cursor.execute(sql, params)
           ^^^^^^^^^^^^^^^^^^^^^^^^^^^^^^^^
  File "D:\Python\Lib\site-packages\django\db\backends\sqlite3\base.py", line 328, in execute
    return super().execute(query, params)
           ^^^^^^^^^^^^^^^^^^^^^^^^^^^^^^
sqlite3.OperationalError: no such table: campaigns_campaignrequest

The above exception was the direct cause of the following exception:

Traceback (most recent call last):
  File "D:\Python\Lib\site-packages\django\core\handlers\exception.py", line 55, in inner
    response = get_response(request)
               ^^^^^^^^^^^^^^^^^^^^^
  File "D:\Python\Lib\site-packages\django\core\handlers\base.py", line 197, in _get_response
    response = wrapped_callback(request, *callback_args, **callback_kwargs)
               ^^^^^^^^^^^^^^^^^^^^^^^^^^^^^^^^^^^^^^^^^^^^^^^^^^^^^^^^^^^^
  File "D:\Python\Lib\site-packages\django\views\decorators\csrf.py", line 56, in wrapper_view
    return view_func(*args, **kwargs)
           ^^^^^^^^^^^^^^^^^^^^^^^^^^
  File "D:\Python\Lib\site-packages\django\views\generic\base.py", line 104, in view
    return self.dispatch(request, *args, **kwargs)
           ^^^^^^^^^^^^^^^^^^^^^^^^^^^^^^^^^^^^^^^
  File "D:\Python\Lib\site-packages\rest_framework\views.py", line 509, in dispatch
    response = self.handle_exception(exc)
               ^^^^^^^^^^^^^^^^^^^^^^^^^^
  File "D:\Python\Lib\site-packages\rest_framework\views.py", line 469, in handle_exception
    self.raise_uncaught_exception(exc)
  File "D:\Python\Lib\site-packages\rest_framework\views.py", line 480, in raise_uncaught_exception
    raise exc
  File "D:\Python\Lib\site-packages\rest_framework\views.py", line 506, in dispatch
    response = handler(request, *args, **kwargs)
               ^^^^^^^^^^^^^^^^^^^^^^^^^^^^^^^^^
  File "D:\Project\Final\FundFusion\campaigns\views.py", line 17, in post
    campaign_request = serializer.save(requester=request.user)
                       ^^^^^^^^^^^^^^^^^^^^^^^^^^^^^^^^^^^^^^^
  File "D:\Python\Lib\site-packages\rest_framework\serializers.py", line 212, in save
    self.instance = self.create(validated_data)
                    ^^^^^^^^^^^^^^^^^^^^^^^^^^^
  File "D:\Python\Lib\site-packages\rest_framework\serializers.py", line 962, in create
    instance = ModelClass._default_manager.create(**validated_data)
               ^^^^^^^^^^^^^^^^^^^^^^^^^^^^^^^^^^^^^^^^^^^^^^^^^^^^
  File "D:\Python\Lib\site-packages\django\db\models\manager.py", line 87, in manager_method
    return getattr(self.get_queryset(), name)(*args, **kwargs)
           ^^^^^^^^^^^^^^^^^^^^^^^^^^^^^^^^^^^^^^^^^^^^^^^^^^^
  File "D:\Python\Lib\site-packages\django\db\models\query.py", line 658, in create
    obj.save(force_insert=True, using=self.db)
  File "D:\Python\Lib\site-packages\django\db\models\base.py", line 814, in save
    self.save_base(
  File "D:\Python\Lib\site-packages\django\db\models\base.py", line 877, in save_base
    updated = self._save_table(
              ^^^^^^^^^^^^^^^^^
  File "D:\Python\Lib\site-packages\django\db\models\base.py", line 1020, in _save_table
    results = self._do_insert(
              ^^^^^^^^^^^^^^^^
  File "D:\Python\Lib\site-packages\django\db\models\base.py", line 1061, in _do_insert
    return manager._insert(
           ^^^^^^^^^^^^^^^^
  File "D:\Python\Lib\site-packages\django\db\models\manager.py", line 87, in manager_method
    return getattr(self.get_queryset(), name)(*args, **kwargs)
           ^^^^^^^^^^^^^^^^^^^^^^^^^^^^^^^^^^^^^^^^^^^^^^^^^^^
  File "D:\Python\Lib\site-packages\django\db\models\query.py", line 1805, in _insert
    return query.get_compiler(using=using).execute_sql(returning_fields)
           ^^^^^^^^^^^^^^^^^^^^^^^^^^^^^^^^^^^^^^^^^^^^^^^^^^^^^^^^^^^^^
  File "D:\Python\Lib\site-packages\django\db\models\sql\compiler.py", line 1822, in execute_sql
    cursor.execute(sql, params)
  File "D:\Python\Lib\site-packages\django\db\backends\utils.py", line 67, in execute
    return self._execute_with_wrappers(
           ^^^^^^^^^^^^^^^^^^^^^^^^^^^^
  File "D:\Python\Lib\site-packages\django\db\backends\utils.py", line 80, in _execute_with_wrappers
    return executor(sql, params, many, context)
           ^^^^^^^^^^^^^^^^^^^^^^^^^^^^^^^^^^^^
  File "D:\Python\Lib\site-packages\django\db\backends\utils.py", line 84, in _execute
    with self.db.wrap_database_errors:
         ^^^^^^^^^^^^^^^^^^^^^^^^^^^^
  File "D:\Python\Lib\site-packages\django\db\utils.py", line 91, in __exit__
    raise dj_exc_value.with_traceback(traceback) from exc_value
  File "D:\Python\Lib\site-packages\django\db\backends\utils.py", line 89, in _execute
    return self.cursor.execute(sql, params)
           ^^^^^^^^^^^^^^^^^^^^^^^^^^^^^^^^
  File "D:\Python\Lib\site-packages\django\db\backends\sqlite3\base.py", line 328, in execute
    return super().execute(query, params)
           ^^^^^^^^^^^^^^^^^^^^^^^^^^^^^^
django.db.utils.OperationalError: no such table: campaigns_campaignrequest
"POST /api/campaign-requests/ HTTP/1.1" 500 145
Internal Server Error: /api/campaign-requests/
Traceback (most recent call last):
  File "D:\Python\Lib\site-packages\django\db\backends\utils.py", line 89, in _execute
    return self.cursor.execute(sql, params)
           ^^^^^^^^^^^^^^^^^^^^^^^^^^^^^^^^
  File "D:\Python\Lib\site-packages\django\db\backends\sqlite3\base.py", line 328, in execute
    return super().execute(query, params)
           ^^^^^^^^^^^^^^^^^^^^^^^^^^^^^^
sqlite3.OperationalError: no such table: campaigns_campaignrequest

The above exception was the direct cause of the following exception:

Traceback (most recent call last):
  File "D:\Python\Lib\site-packages\django\core\handlers\exception.py", line 55, in inner
    response = get_response(request)
               ^^^^^^^^^^^^^^^^^^^^^
  File "D:\Python\Lib\site-packages\django\core\handlers\base.py", line 197, in _get_response
    response = wrapped_callback(request, *callback_args, **callback_kwargs)
               ^^^^^^^^^^^^^^^^^^^^^^^^^^^^^^^^^^^^^^^^^^^^^^^^^^^^^^^^^^^^
  File "D:\Python\Lib\site-packages\django\views\decorators\csrf.py", line 56, in wrapper_view
    return view_func(*args, **kwargs)
           ^^^^^^^^^^^^^^^^^^^^^^^^^^
  File "D:\Python\Lib\site-packages\django\views\generic\base.py", line 104, in view
    return self.dispatch(request, *args, **kwargs)
           ^^^^^^^^^^^^^^^^^^^^^^^^^^^^^^^^^^^^^^^
  File "D:\Python\Lib\site-packages\rest_framework\views.py", line 509, in dispatch
    response = self.handle_exception(exc)
               ^^^^^^^^^^^^^^^^^^^^^^^^^^
  File "D:\Python\Lib\site-packages\rest_framework\views.py", line 469, in handle_exception
    self.raise_uncaught_exception(exc)
  File "D:\Python\Lib\site-packages\rest_framework\views.py", line 480, in raise_uncaught_exception
    raise exc
  File "D:\Python\Lib\site-packages\rest_framework\views.py", line 506, in dispatch
    response = handler(request, *args, **kwargs)
               ^^^^^^^^^^^^^^^^^^^^^^^^^^^^^^^^^
  File "D:\Project\Final\FundFusion\campaigns\views.py", line 17, in post
    campaign_request = serializer.save(requester=request.user)
                       ^^^^^^^^^^^^^^^^^^^^^^^^^^^^^^^^^^^^^^^
  File "D:\Python\Lib\site-packages\rest_framework\serializers.py", line 212, in save
    self.instance = self.create(validated_data)
                    ^^^^^^^^^^^^^^^^^^^^^^^^^^^
  File "D:\Python\Lib\site-packages\rest_framework\serializers.py", line 962, in create
    instance = ModelClass._default_manager.create(**validated_data)
               ^^^^^^^^^^^^^^^^^^^^^^^^^^^^^^^^^^^^^^^^^^^^^^^^^^^^
  File "D:\Python\Lib\site-packages\django\db\models\manager.py", line 87, in manager_method
    return getattr(self.get_queryset(), name)(*args, **kwargs)
           ^^^^^^^^^^^^^^^^^^^^^^^^^^^^^^^^^^^^^^^^^^^^^^^^^^^
  File "D:\Python\Lib\site-packages\django\db\models\query.py", line 658, in create
    obj.save(force_insert=True, using=self.db)
  File "D:\Python\Lib\site-packages\django\db\models\base.py", line 814, in save
    self.save_base(
  File "D:\Python\Lib\site-packages\django\db\models\base.py", line 877, in save_base
    updated = self._save_table(
              ^^^^^^^^^^^^^^^^^
  File "D:\Python\Lib\site-packages\django\db\models\base.py", line 1020, in _save_table
    results = self._do_insert(
              ^^^^^^^^^^^^^^^^
  File "D:\Python\Lib\site-packages\django\db\models\base.py", line 1061, in _do_insert
    return manager._insert(
           ^^^^^^^^^^^^^^^^
  File "D:\Python\Lib\site-packages\django\db\models\manager.py", line 87, in manager_method
    return getattr(self.get_queryset(), name)(*args, **kwargs)
           ^^^^^^^^^^^^^^^^^^^^^^^^^^^^^^^^^^^^^^^^^^^^^^^^^^^
  File "D:\Python\Lib\site-packages\django\db\models\query.py", line 1805, in _insert
    return query.get_compiler(using=using).execute_sql(returning_fields)
           ^^^^^^^^^^^^^^^^^^^^^^^^^^^^^^^^^^^^^^^^^^^^^^^^^^^^^^^^^^^^^
  File "D:\Python\Lib\site-packages\django\db\models\sql\compiler.py", line 1822, in execute_sql
    cursor.execute(sql, params)
  File "D:\Python\Lib\site-packages\django\db\backends\utils.py", line 67, in execute
    return self._execute_with_wrappers(
           ^^^^^^^^^^^^^^^^^^^^^^^^^^^^
  File "D:\Python\Lib\site-packages\django\db\backends\utils.py", line 80, in _execute_with_wrappers
    return executor(sql, params, many, context)
           ^^^^^^^^^^^^^^^^^^^^^^^^^^^^^^^^^^^^
  File "D:\Python\Lib\site-packages\django\db\backends\utils.py", line 84, in _execute
    with self.db.wrap_database_errors:
         ^^^^^^^^^^^^^^^^^^^^^^^^^^^^
  File "D:\Python\Lib\site-packages\django\db\utils.py", line 91, in __exit__
    raise dj_exc_value.with_traceback(traceback) from exc_value
  File "D:\Python\Lib\site-packages\django\db\backends\utils.py", line 89, in _execute
    return self.cursor.execute(sql, params)
           ^^^^^^^^^^^^^^^^^^^^^^^^^^^^^^^^
  File "D:\Python\Lib\site-packages\django\db\backends\sqlite3\base.py", line 328, in execute
    return super().execute(query, params)
           ^^^^^^^^^^^^^^^^^^^^^^^^^^^^^^
django.db.utils.OperationalError: no such table: campaigns_campaignrequest
"POST /api/campaign-requests/ HTTP/1.1" 500 145
Internal Server Error: /api/campaign-requests/
Traceback (most recent call last):
  File "D:\Python\Lib\site-packages\django\db\backends\utils.py", line 89, in _execute
    return self.cursor.execute(sql, params)
           ^^^^^^^^^^^^^^^^^^^^^^^^^^^^^^^^
  File "D:\Python\Lib\site-packages\django\db\backends\sqlite3\base.py", line 328, in execute
    return super().execute(query, params)
           ^^^^^^^^^^^^^^^^^^^^^^^^^^^^^^
sqlite3.OperationalError: no such table: campaigns_campaignrequest

The above exception was the direct cause of the following exception:

Traceback (most recent call last):
  File "D:\Python\Lib\site-packages\django\core\handlers\exception.py", line 55, in inner
    response = get_response(request)
               ^^^^^^^^^^^^^^^^^^^^^
  File "D:\Python\Lib\site-packages\django\core\handlers\base.py", line 197, in _get_response
    response = wrapped_callback(request, *callback_args, **callback_kwargs)
               ^^^^^^^^^^^^^^^^^^^^^^^^^^^^^^^^^^^^^^^^^^^^^^^^^^^^^^^^^^^^
  File "D:\Python\Lib\site-packages\django\views\decorators\csrf.py", line 56, in wrapper_view
    return view_func(*args, **kwargs)
           ^^^^^^^^^^^^^^^^^^^^^^^^^^
  File "D:\Python\Lib\site-packages\django\views\generic\base.py", line 104, in view
    return self.dispatch(request, *args, **kwargs)
           ^^^^^^^^^^^^^^^^^^^^^^^^^^^^^^^^^^^^^^^
  File "D:\Python\Lib\site-packages\rest_framework\views.py", line 509, in dispatch
    response = self.handle_exception(exc)
               ^^^^^^^^^^^^^^^^^^^^^^^^^^
  File "D:\Python\Lib\site-packages\rest_framework\views.py", line 469, in handle_exception
    self.raise_uncaught_exception(exc)
  File "D:\Python\Lib\site-packages\rest_framework\views.py", line 480, in raise_uncaught_exception
    raise exc
  File "D:\Python\Lib\site-packages\rest_framework\views.py", line 506, in dispatch
    response = handler(request, *args, **kwargs)
               ^^^^^^^^^^^^^^^^^^^^^^^^^^^^^^^^^
  File "D:\Project\Final\FundFusion\campaigns\views.py", line 17, in post
    campaign_request = serializer.save(requester=request.user)
                       ^^^^^^^^^^^^^^^^^^^^^^^^^^^^^^^^^^^^^^^
  File "D:\Python\Lib\site-packages\rest_framework\serializers.py", line 212, in save
    self.instance = self.create(validated_data)
                    ^^^^^^^^^^^^^^^^^^^^^^^^^^^
  File "D:\Python\Lib\site-packages\rest_framework\serializers.py", line 962, in create
    instance = ModelClass._default_manager.create(**validated_data)
               ^^^^^^^^^^^^^^^^^^^^^^^^^^^^^^^^^^^^^^^^^^^^^^^^^^^^
  File "D:\Python\Lib\site-packages\django\db\models\manager.py", line 87, in manager_method
    return getattr(self.get_queryset(), name)(*args, **kwargs)
           ^^^^^^^^^^^^^^^^^^^^^^^^^^^^^^^^^^^^^^^^^^^^^^^^^^^
  File "D:\Python\Lib\site-packages\django\db\models\query.py", line 658, in create
    obj.save(force_insert=True, using=self.db)
  File "D:\Python\Lib\site-packages\django\db\models\base.py", line 814, in save
    self.save_base(
  File "D:\Python\Lib\site-packages\django\db\models\base.py", line 877, in save_base
    updated = self._save_table(
              ^^^^^^^^^^^^^^^^^
  File "D:\Python\Lib\site-packages\django\db\models\base.py", line 1020, in _save_table
    results = self._do_insert(
              ^^^^^^^^^^^^^^^^
  File "D:\Python\Lib\site-packages\django\db\models\base.py", line 1061, in _do_insert
    return manager._insert(
           ^^^^^^^^^^^^^^^^
  File "D:\Python\Lib\site-packages\django\db\models\manager.py", line 87, in manager_method
    return getattr(self.get_queryset(), name)(*args, **kwargs)
           ^^^^^^^^^^^^^^^^^^^^^^^^^^^^^^^^^^^^^^^^^^^^^^^^^^^
  File "D:\Python\Lib\site-packages\django\db\models\query.py", line 1805, in _insert
    return query.get_compiler(using=using).execute_sql(returning_fields)
           ^^^^^^^^^^^^^^^^^^^^^^^^^^^^^^^^^^^^^^^^^^^^^^^^^^^^^^^^^^^^^
  File "D:\Python\Lib\site-packages\django\db\models\sql\compiler.py", line 1822, in execute_sql
    cursor.execute(sql, params)
  File "D:\Python\Lib\site-packages\django\db\backends\utils.py", line 67, in execute
    return self._execute_with_wrappers(
           ^^^^^^^^^^^^^^^^^^^^^^^^^^^^
  File "D:\Python\Lib\site-packages\django\db\backends\utils.py", line 80, in _execute_with_wrappers
    return executor(sql, params, many, context)
           ^^^^^^^^^^^^^^^^^^^^^^^^^^^^^^^^^^^^
  File "D:\Python\Lib\site-packages\django\db\backends\utils.py", line 84, in _execute
    with self.db.wrap_database_errors:
         ^^^^^^^^^^^^^^^^^^^^^^^^^^^^
  File "D:\Python\Lib\site-packages\django\db\utils.py", line 91, in __exit__
    raise dj_exc_value.with_traceback(traceback) from exc_value
  File "D:\Python\Lib\site-packages\django\db\backends\utils.py", line 89, in _execute
    return self.cursor.execute(sql, params)
           ^^^^^^^^^^^^^^^^^^^^^^^^^^^^^^^^
  File "D:\Python\Lib\site-packages\django\db\backends\sqlite3\base.py", line 328, in execute
    return super().execute(query, params)
           ^^^^^^^^^^^^^^^^^^^^^^^^^^^^^^
django.db.utils.OperationalError: no such table: campaigns_campaignrequest
"POST /api/campaign-requests/ HTTP/1.1" 500 145
